Workbook
Name ac: '[1]ac code'!$B$2:$C$664
Name acc: '[2]Acc code'!$B$6:$C$774
Name accnt: '[3]ac code'!$B$3:$C$747
Name Account: [4]ACs!$B$4:$C$659
Name Account.: '[3]ac code'!$B$5:$C$757
Name Account1: #REF!
Name Account1: #REF!
Name Account1: #REF!
Name ACCOUNTCODE: '[5]Acc code'!$B$7:$C$971
Name Accounts: '[6]Acc code'!$B$5:$C$758
Name Accounts.: [7]ACs!$B$5:$C$758
Name AJ_AccCode: '[8]Adjusting Journal'!$H$8:$H$3507
Name AJ_Credit: '[8]Adjusting Journal'!$K$8:$K$3507
Name AJ_Date: '[8]Adjusting Journal'!$D$8:$D$3507
Name AJ_Debit: '[8]Adjusting Journal'!$J$8:$J$3507
Name Beg_Bal: #REF!
Name Beg_Bal: #REF!
Name Beg_Bal: #REF!
Name ChartofAccounts: '[8]Chart of Accounts'!$D$5:$D$163
Name ChartofAccountsTable: '[8]Chart of Accounts'!$D$5:$E$163
Name Chequeregistermay2025: #REF!
Name CJ_AccCode: '[8]Cash Journal'!$H$8:$H$3507
Name CJ_Credit: '[8]Cash Journal'!$K$8:$K$3507
Name CJ_Cust_Supplier: '[8]Cash Journal'!$F$8:$F$3507
Name CJ_Date: '[8]Cash Journal'!$D$8:$D$3507
Name CJ_Debit: '[8]Cash Journal'!$J$8:$J$3507
Name CJ_maxdate: '[8]Cash Journal'!$F$4
Name COD: '[9]Ac Code'!$B$1:$C$726
Name CODE: '[9]Ac Code'!$B$1:$C$726
Name Code..: '[5]Acc code'!$B$4:$C$770
Name codes: [10]Sheet2!$B$4:$C$758
Name Codess: '[11]acc code'!$B$6:$C$760
Name Cum_Int: #REF!
Name Cum_Int: #REF!
Name Cum_Int: #REF!
Name CustomerCode: [8]Customer!$F$8:$F$107
Name darc: [12]Utilization!#REF!
Name darc: [12]Utilization!#REF!
Name darc: [12]Utilization!#REF!
Name Data: #REF!
Name Data: #REF!
Name Data: #REF!
Name DEPARTMENT: '[13]dept code'!$B$3:$C$13
Name dept: [14]Dept!$B$3:$C$10
Name dept1: [14]Dept!$B$3:$C$10
Name DEPT2: [9]Dept!$A$3:$B$11
Name Deptment1: '[15]dept code'!$B$3:$C$18
Name DPRT: [16]Dept!$B$3:$C$11
Name dptmnt: '[17]dpt code'!$A$2:$B$10
Name DS: [18]Dept!$B$4:$C$85
Name DummyBukuBesar: '[8]Dummy GL'!$C$3:$L$17502
Name EmployeeID: [8]Employee!$E$9:$E$108
Name End_Bal: #REF!
Name End_Bal: #REF!
Name End_Bal: #REF!
Name Excel_BuiltIn_Print_Area_11: #REF!
Name Excel_BuiltIn_Print_Area_11: #REF!
Name Excel_BuiltIn_Print_Area_11: #REF!
Name Excel_BuiltIn_Print_Area_12: #REF!
Name Excel_BuiltIn_Print_Area_12: #REF!

Sheet Company Code
A1: CODE | B1: NAME OF THE COMPANY | C1: TYPE
A2: MGL001 | B2: Mbogo Mining and General Supply Limited | C2: MINING
A3: NCL001 | B3: Nile Complex Plaza Limited | C3: FUEL
A4: NFL001 | B4: Nyashishi Finance Limited | C4: FINANCE
A5: NIL001 | B5: Nibengo Insurance Limited | C5: INSUARANCE
A6: BAN001 | B6: Barnabas Athanas Nibengo | C6: PROPRIETOR
A7: NHL001 | B7: NILE Holding Limited | C7: HOLDING

Sheet Business Code
A1: CODE | B1: NAME OF COMPANY | C1: CODE | D1: NAME OF BUSINESS UNITS | E1: TYPE
A2: MGL001 | B2: Mbogo Mining and General Supply Limited | C2: MGL0011 | D2: MANUFACTUREING OF COMMERCIAL EXPLOSIVES | E2: MANUFACTURING
C3: MGL0012 | D3: TRADING OF COMERCIAL EXPLOSIVES | E3: TRADING
C4: MGL0013 | D4: BLASTING AND DRILLING SERVICES | E4: SERVICE
C5: MGL0014 | D5: GENERAL SUPPLY | E5: TRADING
A6: NCL001 | B6: Nile Complex Plaza Limited | C6: NCL0011 | D6: NILE OIL: TRADING OF PETROLEUM PRODUCTS
C7: NCL0012 | D7: NILE PUB: TRADING OF FOODS AND DRINKS
C8: NCL0013 | D8: NILE GARAGE: SPARE PARTS, CAR WASH MANTENANCE AND REPAIR SERVICES
C9: NCL0014 | D9: NILE FINANCIAL HUB: CASH POINT SERVICES
A10: NFL001 | B10: Nyashishi Finance Limited | C10: NFL0011 | D10: SMALL AND MEDIUM ENTERPRISES LOAN
C11: NFL0012 | D11: SALARIED WORKERS LOAN
C12: NFL0013 | D12: ASSET LOAN
A13: NIL001 | B13: Nibengo Insurance Limited | C13: NIL0011 | D13: MOTOR VEHICLE INSURANCE
C14: NIL0012 | D14: MOTOR CYCLE INSURANCE
C15: NIL0013 | D15: FIRE INSURANCE
C16: NIL0014 | D16: LIFE INSURANCE
A17: BAN001 | B17: Barnabas Athanas Nibengo | C17: BAN0011 | D17: MAKOROBOI SHOP BEAUTY PRODUCTIS
C18: BAN0012 | D18: NILE SATO SANGALA SHOP
C19: BAN0013 | D19: NILE FRESH SPRINGS WATER

Sheet Location Code Code
A1: CODE | B1: NAME OF COMPANY | C1: CODE | D1: NAME OF BUSINESS UNITS | E1: CODE | F1: NAME OF SALES POINT
A2: MGL001 | B2: Mbogo Mining and General Supply Limited | C2: MGL0011 | D2: MANUFACTURING OF COMMERCIAL EXPLOSIVES | E2: MGL00111 | F2: IHAYABUYAGA MAGU MWANZA
C3: MGL0012 | D3: TRADING OF COMERCIAL EXPLOSIVES | E3: MGL00121 | F3: HEAD OFFICE NYASHISHI MWANZA
E4: MGL00122 | F4: MERERANI MERERANI MANYARA
E5: MGL00123 | F5: MBEZI LUISI UBUNGO DAR ES SALAAM
E6: MGL00124 | F6: RUANDA MBINGA RUVUMA
C7: MGL0013 | D7: BLASTING AND DRILLING SERVICES | E7: MGL00131 | F7: HEAD OFFICE NYASHISHI MWANZA
C8: MGL0014 | D8: GENERAL SUPPLY | E8: MGL00141 | F8: HEAD OFFICE NYASHISHI MWANZA
A9: NCL001 | B9: Nile Complex Plaza Limited | C9: NCL0011 | D9: NILE OIL: TRADING OF PETROLEUM PRODUCTS | E9: NCL00111 | F9: HEAD OFFICE NYASHISHI MWANZA
C10: NCL0012 | D10: NILE PUB: TRADING OF FOODS AND DRINKS | E10: NCL00112 | F10: HEAD OFFICE NYASHISHI MWANZA
C11: NCL0013 | D11: NILE GARAGE: SPARE PARTS, CAR WASH AND SERVICES | E11: NCL00113 | F11: HEAD OFFICE NYASHISHI MWANZA
C12: NCL0014 | D12: NILE FINANCIAL HUB: CASH POINT | E12: NCL00114 | F12: HEAD OFFICE NYASHISHI MWANZA
A13: NFL001 | B13: Nyashishi Finance Limited | C13: NFL0011 | D13: SMALL AND MEDIUM ENTERPRISES LOAN | E13: NFL00111 | F13: HEAD OFFICE NYASHISHI MWANZA
C14: NFL0012 | D14: SALARIED WORKERS LOAN | E14: NFL00112 | F14: HEAD OFFICE NYASHISHI MWANZA
C15: NFL0013 | D15: ASSET LOAN | E15: NFL00113 | F15: HEAD OFFICE NYASHISHI MWANZA
A16: NIL001 | B16: Nibengo Insurance Limited | C16: NIL0011 | D16: MOTOR VEHICLE INSURANCE | E16: NIL00111 | F16: HEAD OFFICE NYASHISHI MWANZA
C17: NIL0012 | D17: MOTOR CYCLE INSURANCE | E17: NIL00112 | F17: HEAD OFFICE NYASHISHI MWANZA
C18: NIL0013 | D18: FIRE INSURANCE | E18: NIL00113 | F18: HEAD OFFICE NYASHISHI MWANZA
C19: NIL0014 | D19: LIFE INSURANCE | E19: NIL00114 | F19: HEAD OFFICE NYASHISHI MWANZA
A20: BAN001 | B20: Barnabas Athanas Nibengo | C20: BAN0011 | D20: NILE FRESH SPRINGS WATER | E20: BAN00131 | F20: RUANDA MBINGA RUVUMA
C21: BAN0012 | D21: NILE SATO SANGALA | E21: BAN00121 | F21: MBEZI LUISI UBUNGO DAR ES SALAAM
E22: BAN00122 | F22: USAGARA MISUNGWI MWANZA

Sheet Department  Codes
A1: CODE | B1: NAME OF DEPARTMENT
A2: FAD001 | B2: Finance and Administration Department
A3: PRD001 | B3: Production Department
A4: BDD001 | B4: Business Development Department
D203: =VLOOKUP(#REF!,'Department Codes'!A2:B4,2,FALSE) -> #REF!

Sheet Section Code
A1: Department Code | B1: Section Code | C1: Name of Section
A2: ='Department Codes'!A2 -> FAD001 | B2: FAD00101 | C2: General Administration Section
A3: ='Department Codes'!B2 -> Finance and Administration Department | B3: FAD00102 | C3: Finance Section
B4: FAD00103 | C4: Microfinance Section
B5: FAD00104 | C5: Insurance Section
B6: FAD00105 | C6: Information Communication Technology Department
B7: FAD00106 | C7: Internal Audit and Control Section
A9: ='Department Codes'!A3 -> PRD001 | B9: PRD00101 | C9: Manufacturing of Commercial Explosive Section
A10: ='Department Codes'!B3 -> Production Department | B10: PRD00102 | C10: Drilling and Blasting Section
B11: PRD00103 | C11: Water Supply Section
B12: PRD00104 | C12: Construction section
B13: PRD00105 | C13: Technology Transfer Research and Innovation section
A15: ='Department Codes'!A4 -> BDD001 | B15: BDD00101 | C15: General Supply Section
A16: ='Department Codes'!B4 -> Business Development Department | B16: BDD00102 | C16: Sales and Marketing Section
B17: BDD00103 | C17: Logistic and freight Management Section
B18: BDD00104 | C18: Store Management Section

Sheet Improved Accounting codes
A3: ENGLISH | B3: ENGLISH | C3: ENGLISH
A4: LIST | B4: LIST OF ACCOUNTS OF THE REVISED CH OF ACCOUNTS | C4: LIST
A5: Codes | B5: Name | C5: Sub Acc Code | D5: Name
A6: 1 | B6: CLASS 1 – EQUITY AND NON-CURRENT LIABILITIES
A7: 10 | B7: Capital and similar
A8: 101 | B8: Share capital
A9: 101101 | B9: Share capital | C9: 10110100 | D9: Subscribed Share Capital
C10: 10110101 | D10: Paid Share Share Capital
C11: 10110102 | D11: pay As You Earn (PAYE)
A12: 102 | B12: Bonuses linked to share capital
A13: 102101 | B13: Bonuses linked to share capital | C13: 10210100 | D13: Bonuses linked to share capital
A14: 103 | B14: Personal capital .
A15: 103101 | B15: Personal capital . | C15: 10310100 | D15: Personal capital .
A16: 104 | B16: Blocked accounts of institutions and branches
A17: 104101 | B17: Blocked accounts of institutions and branches | C17: 10410100 | D17: Blocked accounts of institutions and branches
A18: 105 | B18: Endowment Fund .
A19: 105101 | B19: Endowment Fund . | C19: 10510100 | D19: Endowment Fund .
A20: 108 | B20: Operator's account
A21: 108101 | B21: Operator's account | C21: 10810100 | D21: Operator's account
A22: 109 | B22: Partners, unpaid subscribed capital
A23: 109101 | B23: Partners, unpaid subscribed capital | C23: 10910100 | D23: Partners, unpaid subscribed capital
A24: 11 | B24: Reserves
A25: 111 | B25: Regulatory reserves .
A26: 111101 | B26: Regulatory reserves . | C26: 11110100 | D26: Regulatory reserves .
A27: 112 | B27: Optional reserves
A28: 112101 | B28: Optional reserves | C28: 11210100 | D28: Optional reserves
A29: 116 | B29: Consolidated reserves .
A30: 116101 | B30: Consolidated reserves . | C30: 11610100 | D30: Consolidated reserves .
A31: 117 | B31: Equivalence discrepancies
A32: 117101 | B32: Equivalence discrepancies | C32: 11710100 | D32: Equivalence discrepancies
A33: 12 | B33: Result and carry-over again
A34: 120 | B34: Postponement
A35: 120101 | B35: Postponement | C35: 12010100 | D35: Postponement
A36: 125 | B36: Net profit or loss for the year
A37: 125101 | B37: Net profit or loss for the year | C37: 12510100 | D37: Net profit or loss for the year
A38: 13 | B38: Other equity
A39: 131 | B39: Conversion discrepancies .
A40: 131101 | B40: Conversion discrepancies . | C40: 13110100 | D40: Conversion discrepancies .
A41: 132 | B41: Revaluation deviations
A42: 132101 | B42: Revaluation deviations | C42: 13210100 | D42: Revaluation deviations
...

Sheet General ledger 2025
A1: Account Bank Statement
A2: MBOGO MINING AND GENERAL KISEKE P.O.BOX 6369
A3: Account: 0150481116500 Available Balance: 15,921,784.45 TZS Period: 1 Year Total Value for Credit: 2,615,814,992.61 TZS Total Value for Debit: 2,597,702,089.91 TZS Summary of Book Balance as at 19/12/2025 : 15,921,784.45 TZS Summary of Cleared Balance as at 19/12/2025 : 15,921,784.45 TZS 19/12/2025 11:47:36
A7: Posting Date | B7: P.V.NO. | C7: CHQ N0. | D7: PAYEE | E7: Sub Account Code | F7: Sub Account Description | G7: Account Code | H7: Account Description | I7: Section Code | J7: Section description | K7: Department Code | L7: Department Description | M7: Location code | N7: Location Description | O7: Busines Code | P7: Business Description | Q7: Company Code | R7: Company Description | S7: USD | T7: EXCHANGE RATE | U7: Details | V7: Debit | W7: Credit
A8: 02.01.2025 | D8: CRDB BANK PLC | E8: 56150700 | F8: =VLOOKUP(E8,'Improved Accounting codes'!C89:D2429,2,FALSE) -> CRDB TZS:0150481116500 | G8: 561507 | H8: =VLOOKUP(G8,'Improved Accounting codes'!A61:B2401,2,FALSE) -> Agency Float Account | I8: FAD00102 | J8: =VLOOKUP(I8,'Section Code'!$B$1:$C$17,2,FALSE) -> Finance Section | K8: FAD001 | L8: =VLOOKUP(K8,'Department Codes'!$A$1:$B$4,2,FALSE) -> Finance and Administration Department | M8: MGL00121 | N8: =VLOOKUP(M8,'Location Code Code'!$E$2:$F$22,2,FALSE) -> HEAD OFFICE NYASHISHI MWANZA | O8: MGL0012 | P8: =VLOOKUP(O8,'Business Code'!$C$1:$D$19,2,FALSE) -> TRADING OF COMERCIAL EXPLOSIVES | Q8: MGL001 | R8: =VLOOKUP(Q8,'Company Code'!$A$1:$B$7,2,FALSE) -> Mbogo Mining and General Supply Limited | U8: REF:19426ee2ed61dab3 AGENCY FT AB17358199306989206479:Flavian:K N/A | V8: 3000000 | X8: =IF(V8="", W8, V8) -> 3000000 | Y8: =IF(V8<>"","DR","CR") -> DR
A9: 02.01.2025 | D9: CRDB BANK PLC | E9: 56150600 | F9: =VLOOKUP(E9,'Improved Accounting codes'!C90:D2430,2,FALSE) -> CRDB TZS:0150481116500 | G9: 561506 | H9: =VLOOKUP(G9,'Improved Accounting codes'!A62:B2402,2,FALSE) -> CRDB BANK PLC | I9: FAD00102 | J9: =VLOOKUP(I9,'Section Code'!$B$1:$C$17,2,FALSE) -> Finance Section | K9: FAD001 | L9: =VLOOKUP(K9,'Department Codes'!$A$1:$B$4,2,FALSE) -> Finance and Administration Department | M9: MGL00121 | N9: =VLOOKUP(M9,'Location Code Code'!$E$2:$F$22,2,FALSE) -> HEAD OFFICE NYASHISHI MWANZA | O9: MGL0012 | P9: =VLOOKUP(O9,'Business Code'!$C$1:$D$19,2,FALSE) -> TRADING OF COMERCIAL EXPLOSIVES | Q9: MGL001 | R9: =VLOOKUP(Q9,'Company Code'!$A$1:$B$7,2,FALSE) -> Mbogo Mining and General Supply Limited | U9: REF:19426ee2ed61dab3 AGENCY FT AB17358199306989206479:Flavian:K N/A | W9: 3000000 | X9: =IF(V9="", W9, V9) -> 3000000 | Y9: =IF(V9<>"","DR","CR") -> CR
A10: 02.01.2025 | B10: RV01-02012025 | D10: NEEMA RAPHAEL 0744979075 M -PESA | E10: 60160204 | F10: =VLOOKUP(E10,'Improved Accounting codes'!C91:D2431,2,FALSE) -> Service Cost: Labour Charges | G10: 601602 | H10: =VLOOKUP(G10,'Improved Accounting codes'!A63:B2403,2,FALSE) -> Cost of Services | I10: BDD00102 | J10: =VLOOKUP(I10,'Section Code'!$B$1:$C$17,2,FALSE) -> Sales and Marketing Section | K10: BDD001 | L10: =VLOOKUP(K10,'Department Codes'!$A$1:$B$4,2,FALSE) -> Business Development Department | M10: MGL00121 | N10: =VLOOKUP(M10,'Location Code Code'!$E$2:$F$22,2,FALSE) -> HEAD OFFICE NYASHISHI MWANZA | O10: MGL0012 | P10: =VLOOKUP(O10,'Business Code'!$C$1:$D$19,2,FALSE) -> TRADING OF COMERCIAL EXPLOSIVES | Q10: MGL001 | R10: =VLOOKUP(Q10,'Company Code'!$A$1:$B$7,2,FALSE) -> Mbogo Mining and General Supply Limited | U10: .Being payment for Casual labour 3 people@8000/= for six days | V10: 144000 | X10: =IF(V10="", W10, V10) -> 144000 | Y10: =IF(V10<>"","DR","CR") -> DR
A11: 02.01.2025 | B11: RV01-02012025 | D11: NEEMA RAPHAEL 0744979075 M -PESA | E11: 57250100 | F11: =VLOOKUP(E11,'Improved Accounting codes'!C92:D2432,2,FALSE) -> Cash for office use Mbogo Mining and General Supply Limited | G11: 572501 | H11: =VLOOKUP(G11,'Improved Accounting codes'!A64:B2404,2,FALSE) -> Cash for Office Use | I11: BDD00102 | J11: =VLOOKUP(I11,'Section Code'!$B$1:$C$17,2,FALSE) -> Sales and Marketing Section | K11: BDD001 | L11: =VLOOKUP(K11,'Department Codes'!$A$1:$B$4,2,FALSE) -> Business Development Department | M11: MGL00121 | N11: =VLOOKUP(M11,'Location Code Code'!$E$2:$F$22,2,FALSE) -> HEAD OFFICE NYASHISHI MWANZA | O11: MGL0012 | P11: =VLOOKUP(O11,'Business Code'!$C$1:$D$19,2,FALSE) -> TRADING OF COMERCIAL EXPLOSIVES | Q11: MGL001 | R11: =VLOOKUP(Q11,'Company Code'!$A$1:$B$7,2,FALSE) -> Mbogo Mining and General Supply Limited | U11: .Being payment for Casual labour 3 people@8000/= for six days | W11: 144000 | X11: =IF(V11="", W11, V11) -> 144000 | Y11: =IF(V11<>"","DR","CR") -> CR
A12: 02.01.2025 | B12: RV01-02012025 | D12: NEEMA RAPHAEL 0744979075 M -PESA | E12: 40240100 | F12: =VLOOKUP(E12,'Improved Accounting codes'!C93:D2433,2,FALSE) -> Fixed Asset Suppliers | G12: 402401 | H12: =VLOOKUP(G12,'Improved Accounting codes'!A65:B2405,2,FALSE) -> Fixed Asset Suppliers | I12: BDD00102 | J12: =VLOOKUP(I12,'Section Code'!$B$1:$C$17,2,FALSE) -> Sales and Marketing Section | K12: BDD001 | L12: =VLOOKUP(K12,'Department Codes'!$A$1:$B$4,2,FALSE) -> Business Development Department | M12: MGL00121 | N12: =VLOOKUP(M12,'Location Code Code'!$E$2:$F$22,2,FALSE) -> HEAD OFFICE NYASHISHI MWANZA | O12: MGL0012 | P12: =VLOOKUP(O12,'Business Code'!$C$1:$D$19,2,FALSE) -> TRADING OF COMERCIAL EXPLOSIVES | Q12: MGL001 | R12: =VLOOKUP(Q12,'Company Code'!$A$1:$B$7,2,FALSE) -> Mbogo Mining and General Supply Limited | U12: Being purchase of purchase of sharpening throw 4pcs@4000 | V12: 16000 | X12: =IF(V12="", W12, V12) -> 16000 | Y12: =IF(V12<>"","DR","CR") -> DR
A13: 02.01.2025 | B13: RV01-02012025 | D13: NEEMA RAPHAEL 0744979075 M -PESA | E13: 57250100 | F13: =VLOOKUP(E13,'Improved Accounting codes'!C94:D2434,2,FALSE) -> Cash for office use Mbogo Mining and General Supply Limited | G13: 572501 | H13: =VLOOKUP(G13,'Improved Accounting codes'!A66:B2406,2,FALSE) -> Cash for Office Use | I13: BDD00102 | J13: =VLOOKUP(I13,'Section Code'!$B$1:$C$17,2,FALSE) -> Sales and Marketing Section | K13: BDD001 | L13: =VLOOKUP(K13,'Department Codes'!$A$1:$B$4,2,FALSE) -> Business Development Department | M13: MGL00121 | N13: =VLOOKUP(M13,'Location Code Code'!$E$2:$F$22,2,FALSE) -> HEAD OFFICE NYASHISHI MWANZA | O13: MGL0012 | P13: =VLOOKUP(O13,'Business Code'!$C$1:$D$19,2,FALSE) -> TRADING OF COMERCIAL EXPLOSIVES | Q13: MGL001 | R13: =VLOOKUP(Q13,'Company Code'!$A$1:$B$7,2,FALSE) -> Mbogo Mining and General Supply Limited | U13: Being purchase of purchase of sharpening throw 4pcs@4000 | W13: 16000 | X13: =IF(V13="", W13, V13) -> 16000 | Y13: =IF(V13<>"","DR","CR") -> CR
A14: 02.01.2025 | B14: RV01-02012025 | D14: NEEMA RAPHAEL 0744979075 M -PESA | E14: 40240100 | F14: =VLOOKUP(E14,'Improved Accounting codes'!C95:D2435,2,FALSE) -> Fixed Asset Suppliers | G14: 402401 | H14: =VLOOKUP(G14,'Improved Accounting codes'!A67:B2407,2,FALSE) -> Fixed Asset Suppliers | I14: BDD00102 | J14: =VLOOKUP(I14,'Section Code'!$B$1:$C$17,2,FALSE) -> Sales and Marketing Section | K14: BDD001 | L14: =VLOOKUP(K14,'Department Codes'!$A$1:$B$4,2,FALSE) -> Business Development Department | M14: MGL00121 | N14: =VLOOKUP(M14,'Location Code Code'!$E$2:$F$22,2,FALSE) -> HEAD OFFICE NYASHISHI MWANZA | O14: MGL0012 | P14: =VLOOKUP(O14,'Business Code'!$C$1:$D$19,2,FALSE) -> TRADING OF COMERCIAL EXPLOSIVES | Q14: MGL001 | R14: =VLOOKUP(Q14,'Company Code'!$A$1:$B$7,2,FALSE) -> Mbogo Mining and General Supply Limited | U14: Being payment for purchase of wood chiper 10 pcs@2000 | V14: 20000 | X14: =IF(V14="", W14, V14) -> 20000 | Y14: =IF(V14<>"","DR","CR") -> DR
A15: 02.01.2025 | B15: RV01-02012025 | D15: NEEMA RAPHAEL 0744979075 M -PESA | E15: 57250100 | F15: =VLOOKUP(E15,'Improved Accounting codes'!C96:D2436,2,FALSE) -> Cash for office use Mbogo Mining and General Supply Limited | G15: 572501 | H15: =VLOOKUP(G15,'Improved Accounting codes'!A68:B2408,2,FALSE) -> Cash for Office Use | I15: BDD00102 | J15: =VLOOKUP(I15,'Section Code'!$B$1:$C$17,2,FALSE) -> Sales and Marketing Section | K15: BDD001 | L15: =VLOOKUP(K15,'Department Codes'!$A$1:$B$4,2,FALSE) -> Business Development Department | M15: MGL00121 | N15: =VLOOKUP(M15,'Location Code Code'!$E$2:$F$22,2,FALSE) -> HEAD OFFICE NYASHISHI MWANZA | O15: MGL0012 | P15: =VLOOKUP(O15,'Business Code'!$C$1:$D$19,2,FALSE) -> TRADING OF COMERCIAL EXPLOSIVES | Q15: MGL001 | R15: =VLOOKUP(Q15,'Company Code'!$A$1:$B$7,2,FALSE) -> Mbogo Mining and General Supply Limited | U15: Being payment for purchase of wood chiper 10 pcs@2000 | W15: 20000 | X15: =IF(V15="", W15, V15) -> 20000 | Y15: =IF(V15<>"","DR","CR") -> CR
A16: 02.01.2025 | B16: RV01-02012025 | D16: NEEMA RAPHAEL 0744979075 M -PESA | E16: 40240100 | F16: =VLOOKUP(E16,'Improved Accounting codes'!C97:D2437,2,FALSE) -> Fixed Asset Suppliers | G16: 572501 | H16: =VLOOKUP(G16,'Improved Accounting codes'!A69:B2409,2,FALSE) -> Cash for Office Use | I16: BDD00102 | J16: =VLOOKUP(I16,'Section Code'!$B$1:$C$17,2,FALSE) -> Sales and Marketing Section | K16: BDD001 | L16: =VLOOKUP(K16,'Department Codes'!$A$1:$B$4,2,FALSE) -> Business Development Department | M16: MGL00121 | N16: =VLOOKUP(M16,'Location Code Code'!$E$2:$F$22,2,FALSE) -> HEAD OFFICE NYASHISHI MWANZA | O16: MGL0012 | P16: =VLOOKUP(O16,'Business Code'!$C$1:$D$19,2,FALSE) -> TRADING OF COMERCIAL EXPLOSIVES | Q16: MGL001 | R16: =VLOOKUP(Q16,'Company Code'!$A$1:$B$7,2,FALSE) -> Mbogo Mining and General Supply Limited | U16: Being payment forpurchase of knife 2 pcs@7000 | V16: 14000 | X16: =IF(V16="", W16, V16) -> 14000 | Y16: =IF(V16<>"","DR","CR") -> DR
A17: 02.01.2025 | B17: RV01-02012025 | D17: NEEMA RAPHAEL 0744979075 M -PESA | E17: 57250100 | F17: =VLOOKUP(E17,'Improved Accounting codes'!C98:D2438,2,FALSE) -> Cash for office use Mbogo Mining and General Supply Limited | G17: 572501 | H17: =VLOOKUP(G17,'Improved Accounting codes'!A70:B2410,2,FALSE) -> Cash for Office Use | I17: BDD00102 | J17: =VLOOKUP(I17,'Section Code'!$B$1:$C$17,2,FALSE) -> Sales and Marketing Section | K17: BDD001 | L17: =VLOOKUP(K17,'Department Codes'!$A$1:$B$4,2,FALSE) -> Business Development Department | M17: MGL00121 | N17: =VLOOKUP(M17,'Location Code Code'!$E$2:$F$22,2,FALSE) -> HEAD OFFICE NYASHISHI MWANZA | O17: MGL0012 | P17: =VLOOKUP(O17,'Business Code'!$C$1:$D$19,2,FALSE) -> TRADING OF COMERCIAL EXPLOSIVES | Q17: MGL001 | R17: =VLOOKUP(Q17,'Company Code'!$A$1:$B$7,2,FALSE) -> Mbogo Mining and General Supply Limited | U17: Being payment forpurchase of knife 2 pcs@7000 | W17: 14000 | X17: =IF(V17="", W17, V17) -> 14000 | Y17: =IF(V17<>"","DR","CR") -> CR
A18: 02.01.2025 | B18: RV01-02012025 | D18: CRDB BANK PLC | E18: 63860710 | F18: =VLOOKUP(E18,'Improved Accounting codes'!C99:D2439,2,FALSE) -> CRDB TZS:0150481116500 | G18: 638607 | H18: =VLOOKUP(G18,'Improved Accounting codes'!A71:B2411,2,FALSE) -> Bank Charges | I18: FAD00102 | J18: =VLOOKUP(I18,'Section Code'!$B$1:$C$17,2,FALSE) -> Finance Section | K18: FAD001 | L18: =VLOOKUP(K18,'Department Codes'!$A$1:$B$4,2,FALSE) -> Finance and Administration Department | M18: MGL00121 | N18: =VLOOKUP(M18,'Location Code Code'!$E$2:$F$22,2,FALSE) -> HEAD OFFICE NYASHISHI MWANZA | O18: MGL0012 | P18: =VLOOKUP(O18,'Business Code'!$C$1:$D$19,2,FALSE) -> TRADING OF COMERCIAL EXPLOSIVES | Q18: MGL001 | R18: =VLOOKUP(Q18,'Company Code'!$A$1:$B$7,2,FALSE) -> Mbogo Mining and General Supply Limited | U18: Transaction cost.Tsh 3,700 | V18: 3700 | X18: =IF(V18="", W18, V18) -> 3700 | Y18: =IF(V18<>"","DR","CR") -> DR
A19: 02.01.2025 | B19: RV01-02012025 | D19: CRDB BANK PLC | E19: 56150600 | F19: =VLOOKUP(E19,'Improved Accounting codes'!C100:D2440,2,FALSE) -> CRDB TZS:0150481116500 | G19: 561506 | H19: =VLOOKUP(G19,'Improved Accounting codes'!A72:B2412,2,FALSE) -> CRDB BANK PLC | I19: FAD00102 | J19: =VLOOKUP(I19,'Section Code'!$B$1:$C$17,2,FALSE) -> Finance Section | K19: FAD001 | L19: =VLOOKUP(K19,'Department Codes'!$A$1:$B$4,2,FALSE) -> Finance and Administration Department | M19: MGL00121 | N19: =VLOOKUP(M19,'Location Code Code'!$E$2:$F$22,2,FALSE) -> HEAD OFFICE NYASHISHI MWANZA | O19: MGL0012 | P19: =VLOOKUP(O19,'Business Code'!$C$1:$D$19,2,FALSE) -> TRADING OF COMERCIAL EXPLOSIVES | Q19: MGL001 | R19: =VLOOKUP(Q19,'Company Code'!$A$1:$B$7,2,FALSE) -> Mbogo Mining and General Supply Limited | U19: Transaction cost.Tsh 3,700 | W19: 3700 | X19: =IF(V19="", W19, V19) -> 3700 | Y19: =IF(V19<>"","DR","CR") -> CR
A20: 02.01.2025 | B20: RV01-02012025 | D20: SHABANI MERERE MPESA | E20: 62360104 | F20: =VLOOKUP(E20,'Improved Accounting codes'!C101:D2441,2,FALSE) -> Accomodation, Transport and meals expense | G20: 623601 | H20: =VLOOKUP(G20,'Improved Accounting codes'!A73:B2413,2,FALSE) -> Staff transport | I20: BDD00102 | J20: =VLOOKUP(I20,'Section Code'!$B$1:$C$17,2,FALSE) -> Sales and Marketing Section | K20: BDD001 | L20: =VLOOKUP(K20,'Department Codes'!$A$1:$B$4,2,FALSE) -> Business Development Department | M20: MGL00121 | N20: =VLOOKUP(M20,'Location Code Code'!$E$2:$F$22,2,FALSE) -> HEAD OFFICE NYASHISHI MWANZA | O20: MGL0012 | P20: =VLOOKUP(O20,'Business Code'!$C$1:$D$19,2,FALSE) -> TRADING OF COMERCIAL EXPLOSIVES | Q20: MGL001 | R20: =VLOOKUP(Q20,'Company Code'!$A$1:$B$7,2,FALSE) -> Mbogo Mining and General Supply Limited | U20: Being payment for meals and accomodation | V20: 400000 | X20: =IF(V20="", W20, V20) -> 400000 | Y20: =IF(V20<>"","DR","CR") -> DR
A21: 02.01.2025 | B21: RV01-02012025 | D21: SHABANI MERERE MPESA | E21: 57250100 | F21: =VLOOKUP(E21,'Improved Accounting codes'!C102:D2442,2,FALSE) -> Cash for office use Mbogo Mining and General Supply Limited | G21: 572501 | H21: =VLOOKUP(G21,'Improved Accounting codes'!A74:B2414,2,FALSE) -> Cash for Office Use | I21: BDD00102 | J21: =VLOOKUP(I21,'Section Code'!$B$1:$C$17,2,FALSE) -> Sales and Marketing Section | K21: BDD001 | L21: =VLOOKUP(K21,'Department Codes'!$A$1:$B$4,2,FALSE) -> Business Development Department | M21: MGL00121 | N21: =VLOOKUP(M21,'Location Code Code'!$E$2:$F$22,2,FALSE) -> HEAD OFFICE NYASHISHI MWANZA | O21: MGL0012 | P21: =VLOOKUP(O21,'Business Code'!$C$1:$D$19,2,FALSE) -> TRADING OF COMERCIAL EXPLOSIVES | Q21: MGL001 | R21: =VLOOKUP(Q21,'Company Code'!$A$1:$B$7,2,FALSE) -> Mbogo Mining and General Supply Limited | U21: Being payment for meals and accomodation | W21: 400000 | X21: =IF(V21="", W21, V21) -> 400000 | Y21: =IF(V21<>"","DR","CR") -> CR
A22: 02.01.2025 | B22: RV01-02012025 | D22: ZAWADI MWASONGWE 43010002631-NMB | E22: 6386051 | F22: =VLOOKUP(E22,'Improved Accounting codes'!C103:D2443,2,FALSE) -> #N/A | G22: 638605 | H22: =VLOOKUP(G22,'Improved Accounting codes'!A75:B2415,2,FALSE) -> Security Charges | I22: BDD00102 | J22: =VLOOKUP(I22,'Section Code'!$B$1:$C$17,2,FALSE) -> Sales and Marketing Section | K22: BDD001 | L22: =VLOOKUP(K22,'Department Codes'!$A$1:$B$4,2,FALSE) -> Business Development Department | M22: MGL00121 | N22: =VLOOKUP(M22,'Location Code Code'!$E$2:$F$22,2,FALSE) -> HEAD OFFICE NYASHISHI MWANZA | O22: MGL0012 | P22: =VLOOKUP(O22,'Business Code'!$C$1:$D$19,2,FALSE) -> TRADING OF COMERCIAL EXPLOSIVES | Q22: MGL001 | R22: =VLOOKUP(Q22,'Company Code'!$A$1:$B$7,2,FALSE) -> Mbogo Mining and General Supply Limited | U22: Being payment for security the month of November 2024. | V22: 300000 | X22: =IF(V22="", W22, V22) -> 300000 | Y22: =IF(V22<>"","DR","CR") -> DR
A23: 02.01.2025 | B23: RV01-02012025 | D23: ZAWADI MWASONGWE 43010002631-NMB | E23: 57250100 | F23: =VLOOKUP(E23,'Improved Accounting codes'!C104:D2444,2,FALSE) -> Cash for office use Mbogo Mining and General Supply Limited | G23: 572501 | H23: =VLOOKUP(G23,'Improved Accounting codes'!A76:B2416,2,FALSE) -> Cash for Office Use | I23: BDD00102 | J23: =VLOOKUP(I23,'Section Code'!$B$1:$C$17,2,FALSE) -> Sales and Marketing Section | K23: BDD001 | L23: =VLOOKUP(K23,'Department Codes'!$A$1:$B$4,2,FALSE) -> Business Development Department | M23: MGL00121 | N23: =VLOOKUP(M23,'Location Code Code'!$E$2:$F$22,2,FALSE) -> HEAD OFFICE NYASHISHI MWANZA | O23: MGL0012 | P23: =VLOOKUP(O23,'Business Code'!$C$1:$D$19,2,FALSE) -> TRADING OF COMERCIAL EXPLOSIVES | Q23: MGL001 | R23: =VLOOKUP(Q23,'Company Code'!$A$1:$B$7,2,FALSE) -> Mbogo Mining and General Supply Limited | U23: Being payment for security the month of November 2024. | W23: 30000 | X23: =IF(V23="", W23, V23) -> 30000 | Y23: =IF(V23<>"","DR","CR") -> CR
A24: 02.01.2025 | B24: RV01-02012025 | D24: EPIFANIA ODANCE | E24: 63860102 | F24: =VLOOKUP(E24,'Improved Accounting codes'!C105:D2445,2,FALSE) -> Charging Battery | G24: 638601 | H24: =VLOOKUP(G24,'Improved Accounting codes'!A77:B2417,2,FALSE) -> Utilities | I24: FAD00102 | J24: =VLOOKUP(I24,'Section Code'!$B$1:$C$17,2,FALSE) -> Finance Section | K24: FAD001 | L24: =VLOOKUP(K24,'Department Codes'!$A$1:$B$4,2,FALSE) -> Finance and Administration Department | M24: MGL00121 | N24: =VLOOKUP(M24,'Location Code Code'!$E$2:$F$22,2,FALSE) -> HEAD OFFICE NYASHISHI MWANZA | O24: MGL0012 | P24: =VLOOKUP(O24,'Business Code'!$C$1:$D$19,2,FALSE) -> TRADING OF COMERCIAL EXPLOSIVES | Q24: MGL001 | R24: =VLOOKUP(Q24,'Company Code'!$A$1:$B$7,2,FALSE) -> Mbogo Mining and General Supply Limited | U24: Being payment for chargng batery | V24: 3000 | X24: =IF(V24="", W24, V24) -> 3000 | Y24: =IF(V24<>"","DR","CR") -> DR
A25: 02.01.2025 | B25: RV01-02012025 | D25: EPIFANIA ODANCE | E25: 57250100 | F25: =VLOOKUP(E25,'Improved Accounting codes'!C106:D2446,2,FALSE) -> Cash for office use Mbogo Mining and General Supply Limited | G25: 572501 | H25: =VLOOKUP(G25,'Improved Accounting codes'!A78:B2418,2,FALSE) -> Cash for Office Use | I25: FAD00102 | J25: =VLOOKUP(I25,'Section Code'!$B$1:$C$17,2,FALSE) -> Finance Section | K25: FAD001 | L25: =VLOOKUP(K25,'Department Codes'!$A$1:$B$4,2,FALSE) -> Finance and Administration Department | M25: MGL00121 | N25: =VLOOKUP(M25,'Location Code Code'!$E$2:$F$22,2,FALSE) -> HEAD OFFICE NYASHISHI MWANZA | O25: MGL0012 | P25: =VLOOKUP(O25,'Business Code'!$C$1:$D$19,2,FALSE) -> TRADING OF COMERCIAL EXPLOSIVES | Q25: MGL001 | R25: =VLOOKUP(Q25,'Company Code'!$A$1:$B$7,2,FALSE) -> Mbogo Mining and General Supply Limited | U25: Being payment for chargng batery | W25: 3000 | X25: =IF(V25="", W25, V25) -> 3000 | Y25: =IF(V25<>"","DR","CR") -> CR
A26: 02.01.2025 | B26: RV01-02012025 | D26: BBELINDA FREEMAN MIX BY YA YAS 0676302325 | E26: 62360104 | F26: =VLOOKUP(E26,'Improved Accounting codes'!C107:D2447,2,FALSE) -> Accomodation, Transport and meals expense | G26: 623601 | H26: =VLOOKUP(G26,'Improved Accounting codes'!A79:B2419,2,FALSE) -> Staff transport | I26: FAD00102 | J26: =VLOOKUP(I26,'Section Code'!$B$1:$C$17,2,FALSE) -> Finance Section | K26: FAD001 | L26: =VLOOKUP(K26,'Department Codes'!$A$1:$B$4,2,FALSE) -> Finance and Administration Department | M26: MGL00121 | N26: =VLOOKUP(M26,'Location Code Code'!$E$2:$F$22,2,FALSE) -> HEAD OFFICE NYASHISHI MWANZA | O26: MGL0012 | P26: =VLOOKUP(O26,'Business Code'!$C$1:$D$19,2,FALSE) -> TRADING OF COMERCIAL EXPLOSIVES | Q26: MGL001 | R26: =VLOOKUP(Q26,'Company Code'!$A$1:$B$7,2,FALSE) -> Mbogo Mining and General Supply Limited | U26: Being payment for Transport fare to Ihayabuyaga site | V26: 20000 | X26: =IF(V26="", W26, V26) -> 20000 | Y26: =IF(V26<>"","DR","CR") -> DR
A27: 02.01.2025 | B27: RV01-02012025 | D27: BBELINDA FREEMAN MIX BY YA YAS 0676302325 | E27: 57250100 | F27: =VLOOKUP(E27,'Improved Accounting codes'!C108:D2448,2,FALSE) -> Cash for office use Mbogo Mining and General Supply Limited | G27: 572501 | H27: =VLOOKUP(G27,'Improved Accounting codes'!A80:B2420,2,FALSE) -> Cash for Office Use | I27: FAD00102 | J27: =VLOOKUP(I27,'Section Code'!$B$1:$C$17,2,FALSE) -> Finance Section | K27: FAD001 | L27: =VLOOKUP(K27,'Department Codes'!$A$1:$B$4,2,FALSE) -> Finance and Administration Department | M27: MGL00121 | N27: =VLOOKUP(M27,'Location Code Code'!$E$2:$F$22,2,FALSE) -> HEAD OFFICE NYASHISHI MWANZA | O27: MGL0012 | P27: =VLOOKUP(O27,'Business Code'!$C$1:$D$19,2,FALSE) -> TRADING OF COMERCIAL EXPLOSIVES | Q27: MGL001 | R27: =VLOOKUP(Q27,'Company Code'!$A$1:$B$7,2,FALSE) -> Mbogo Mining and General Supply Limited | U27: Being payment for Transport fare to Ihayabuyaga site | W27: 20000 | X27: =IF(V27="", W27, V27) -> 20000 | Y27: =IF(V27<>"","DR","CR") -> CR
A28: 02.01.2025 | B28: RV01-02012025 | D28: GASPER LEONARD MPESA 076542761 | E28: 62760101 | F28: =VLOOKUP(E28,'Improved Accounting codes'!C109:D2449,2,FALSE) -> Spare parts | G28: 627601 | H28: =VLOOKUP(G28,'Improved Accounting codes'!A81:B2421,2,FALSE) -> Spare parts, Repair,Acetone and Maintenance | I28: FAD00102 | J28: =VLOOKUP(I28,'Section Code'!$B$1:$C$17,2,FALSE) -> Finance Section | K28: FAD001 | L28: =VLOOKUP(K28,'Department Codes'!$A$1:$B$4,2,FALSE) -> Finance and Administration Department | M28: MGL00121 | N28: =VLOOKUP(M28,'Location Code Code'!$E$2:$F$22,2,FALSE) -> HEAD OFFICE NYASHISHI MWANZA | O28: MGL0012 | P28: =VLOOKUP(O28,'Business Code'!$C$1:$D$19,2,FALSE) -> TRADING OF COMERCIAL EXPLOSIVES | Q28: MGL001 | R28: =VLOOKUP(Q28,'Company Code'!$A$1:$B$7,2,FALSE) -> Mbogo Mining and General Supply Limited | U28: Being payment for spare parts | V28: 2000000 | X28: =IF(V28="", W28, V28) -> 2000000 | Y28: =IF(V28<>"","DR","CR") -> DR
A29: 02.01.2025 | B29: RV01-02012025 | D29: GASPER LEONARD MPESA 076542761 | E29: 57250100 | F29: =VLOOKUP(E29,'Improved Accounting codes'!C110:D2450,2,FALSE) -> Cash for office use Mbogo Mining and General Supply Limited | G29: 572501 | H29: =VLOOKUP(G29,'Improved Accounting codes'!A82:B2422,2,FALSE) -> Cash for Office Use | I29: BDD00102 | J29: =VLOOKUP(I29,'Section Code'!$B$1:$C$17,2,FALSE) -> Sales and Marketing Section | K29: BDD001 | L29: =VLOOKUP(K29,'Department Codes'!$A$1:$B$4,2,FALSE) -> Business Development Department | M29: MGL00121 | N29: =VLOOKUP(M29,'Location Code Code'!$E$2:$F$22,2,FALSE) -> HEAD OFFICE NYASHISHI MWANZA | O29: MGL0012 | P29: =VLOOKUP(O29,'Business Code'!$C$1:$D$19,2,FALSE) -> TRADING OF COMERCIAL EXPLOSIVES | Q29: MGL001 | R29: =VLOOKUP(Q29,'Company Code'!$A$1:$B$7,2,FALSE) -> Mbogo Mining and General Supply Limited | U29: Being payment for spare parts | W29: 2000000 | X29: =IF(V29="", W29, V29) -> 2000000 | Y29: =IF(V29<>"","DR","CR") -> CR
A30: 02.01.2025 | B30: RV01-02012025 | D30: BENJAMINI SABUNI MIX BY YAS 0655184402 | E30: 60160205 | F30: =VLOOKUP(E30,'Improved Accounting codes'!C111:D2451,2,FALSE) -> Service cost: Processing Charges | G30: 601602 | H30: =VLOOKUP(G30,'Improved Accounting codes'!A83:B2423,2,FALSE) -> Cost of Services | I30: BDD00102 | J30: =VLOOKUP(I30,'Section Code'!$B$1:$C$17,2,FALSE) -> Sales and Marketing Section | K30: BDD001 | L30: =VLOOKUP(K30,'Department Codes'!$A$1:$B$4,2,FALSE) -> Business Development Department | M30: MGL00121 | N30: =VLOOKUP(M30,'Location Code Code'!$E$2:$F$22,2,FALSE) -> HEAD OFFICE NYASHISHI MWANZA | O30: MGL0012 | P30: =VLOOKUP(O30,'Business Code'!$C$1:$D$19,2,FALSE) -> TRADING OF COMERCIAL EXPLOSIVES | Q30: MGL001 | R30: =VLOOKUP(Q30,'Company Code'!$A$1:$B$7,2,FALSE) -> Mbogo Mining and General Supply Limited | U30: Being payment for production of ANFO | V30: 1050750 | X30: =IF(V30="", W30, V30) -> 1050750 | Y30: =IF(V30<>"","DR","CR") -> DR
A31: 02.01.2025 | B31: RV01-02012025 | D31: BENJAMINI SABUNI MIX BY YAS 0655184402 | E31: 57250100 | F31: =VLOOKUP(E31,'Improved Accounting codes'!C112:D2452,2,FALSE) -> Cash for office use Mbogo Mining and General Supply Limited | G31: 572501 | H31: =VLOOKUP(G31,'Improved Accounting codes'!A84:B2424,2,FALSE) -> Cash for Office Use | I31: BDD00102 | J31: =VLOOKUP(I31,'Section Code'!$B$1:$C$17,2,FALSE) -> Sales and Marketing Section | K31: BDD001 | L31: =VLOOKUP(K31,'Department Codes'!$A$1:$B$4,2,FALSE) -> Business Development Department | M31: MGL00121 | N31: =VLOOKUP(M31,'Location Code Code'!$E$2:$F$22,2,FALSE) -> HEAD OFFICE NYASHISHI MWANZA | O31: MGL0012 | P31: =VLOOKUP(O31,'Business Code'!$C$1:$D$19,2,FALSE) -> TRADING OF COMERCIAL EXPLOSIVES | Q31: MGL001 | R31: =VLOOKUP(Q31,'Company Code'!$A$1:$B$7,2,FALSE) -> Mbogo Mining and General Supply Limited | U31: Being payment for production of ANFO | W31: 1050750 | X31: =IF(V31="", W31, V31) -> 1050750 | Y31: =IF(V31<>"","DR","CR") -> CR
A32: 02.01.2025 | B32: RV01-02012025 | D32: BBELINDA FREEMAN MIX BY YA YAS 0676302325 | E32: 62560200 | F32: =VLOOKUP(E32,'Improved Accounting codes'!C113:D2453,2,FALSE) -> TRA Penalties | G32: 625602 | H32: =VLOOKUP(G32,'Improved Accounting codes'!A85:B2425,2,FALSE) -> Penalties Fines and Interests | I32: FAD00102 | J32: =VLOOKUP(I32,'Section Code'!$B$1:$C$17,2,FALSE) -> Finance Section | K32: FAD001 | L32: =VLOOKUP(K32,'Department Codes'!$A$1:$B$4,2,FALSE) -> Finance and Administration Department | M32: MGL00121 | N32: =VLOOKUP(M32,'Location Code Code'!$E$2:$F$22,2,FALSE) -> HEAD OFFICE NYASHISHI MWANZA | O32: MGL0012 | P32: =VLOOKUP(O32,'Business Code'!$C$1:$D$19,2,FALSE) -> TRADING OF COMERCIAL EXPLOSIVES | Q32: MGL001 | R32: =VLOOKUP(Q32,'Company Code'!$A$1:$B$7,2,FALSE) -> Mbogo Mining and General Supply Limited | U32: Being payment for fine for RATRA | V32: 250000 | X32: =IF(V32="", W32, V32) -> 250000 | Y32: =IF(V32<>"","DR","CR") -> DR
A33: 02.01.2025 | B33: RV01-02012025 | D33: BBELINDA FREEMAN MIX BY YA YAS 0676302325 | E33: 57250100 | F33: =VLOOKUP(E33,'Improved Accounting codes'!C114:D2454,2,FALSE) -> Cash for office use Mbogo Mining and General Supply Limited | G33: 572501 | H33: =VLOOKUP(G33,'Improved Accounting codes'!A86:B2426,2,FALSE) -> Cash for Office Use | I33: FAD00102 | J33: =VLOOKUP(I33,'Section Code'!$B$1:$C$17,2,FALSE) -> Finance Section | K33: FAD001 | L33: =VLOOKUP(K33,'Department Codes'!$A$1:$B$4,2,FALSE) -> Finance and Administration Department | M33: MGL00121 | N33: =VLOOKUP(M33,'Location Code Code'!$E$2:$F$22,2,FALSE) -> HEAD OFFICE NYASHISHI MWANZA | O33: MGL0012 | P33: =VLOOKUP(O33,'Business Code'!$C$1:$D$19,2,FALSE) -> TRADING OF COMERCIAL EXPLOSIVES | Q33: MGL001 | R33: =VLOOKUP(Q33,'Company Code'!$A$1:$B$7,2,FALSE) -> Mbogo Mining and General Supply Limited | U33: Being payment for fine for RATRA | W33: 250000 | X33: =IF(V33="", W33, V33) -> 250000 | Y33: =IF(V33<>"","DR","CR") -> CR
A34: 02.01.2025 | B34: RV01-02012025 | D34: BARNABAS NIBENGO MPESA 0765427622 | E34: 62360104 | F34: =VLOOKUP(E34,'Improved Accounting codes'!C115:D2455,2,FALSE) -> Accomodation, Transport and meals expense | G34: 623601 | H34: =VLOOKUP(G34,'Improved Accounting codes'!A87:B2427,2,FALSE) -> Staff transport | I34: BDD00102 | J34: =VLOOKUP(I34,'Section Code'!$B$1:$C$17,2,FALSE) -> Sales and Marketing Section | K34: BDD001 | L34: =VLOOKUP(K34,'Department Codes'!$A$1:$B$4,2,FALSE) -> Business Development Department | M34: MGL00121 | N34: =VLOOKUP(M34,'Location Code Code'!$E$2:$F$22,2,FALSE) -> HEAD OFFICE NYASHISHI MWANZA | O34: MGL0012 | P34: =VLOOKUP(O34,'Business Code'!$C$1:$D$19,2,FALSE) -> TRADING OF COMERCIAL EXPLOSIVES | Q34: MGL001 | R34: =VLOOKUP(Q34,'Company Code'!$A$1:$B$7,2,FALSE) -> Mbogo Mining and General Supply Limited | U34: .Being payment for Meals and Accomodation | V34: 2550000 | X34: =IF(V34="", W34, V34) -> 2550000 | Y34: =IF(V34<>"","DR","CR") -> DR
A35: 02.01.2025 | B35: RV01-02012025 | D35: BARNABAS NIBENGO MPESA 0765427622 | E35: 57250100 | F35: =VLOOKUP(E35,'Improved Accounting codes'!C116:D2456,2,FALSE) -> Cash for office use Mbogo Mining and General Supply Limited | G35: 572501 | H35: =VLOOKUP(G35,'Improved Accounting codes'!A88:B2428,2,FALSE) -> Cash for Office Use | I35: BDD00102 | J35: =VLOOKUP(I35,'Section Code'!$B$1:$C$17,2,FALSE) -> Sales and Marketing Section | K35: BDD001 | L35: =VLOOKUP(K35,'Department Codes'!$A$1:$B$4,2,FALSE) -> Business Development Department | M35: MGL00121 | N35: =VLOOKUP(M35,'Location Code Code'!$E$2:$F$22,2,FALSE) -> HEAD OFFICE NYASHISHI MWANZA | O35: MGL0012 | P35: =VLOOKUP(O35,'Business Code'!$C$1:$D$19,2,FALSE) -> TRADING OF COMERCIAL EXPLOSIVES | Q35: MGL001 | R35: =VLOOKUP(Q35,'Company Code'!$A$1:$B$7,2,FALSE) -> Mbogo Mining and General Supply Limited | U35: .Being payment for Meals and Accomodation | W35: 2550000 | X35: =IF(V35="", W35, V35) -> 2550000 | Y35: =IF(V35<>"","DR","CR") -> CR
A36: 02.01.2025 | B36: RV01-02012025 | D36: ANISET MABULA | E36: 6386051 | F36: =VLOOKUP(E36,'Improved Accounting codes'!C117:D2457,2,FALSE) -> #N/A | G36: 638605 | H36: =VLOOKUP(G36,'Improved Accounting codes'!A89:B2429,2,FALSE) -> Security Charges | I36: BDD00102 | J36: =VLOOKUP(I36,'Section Code'!$B$1:$C$17,2,FALSE) -> Sales and Marketing Section | K36: BDD001 | L36: =VLOOKUP(K36,'Department Codes'!$A$1:$B$4,2,FALSE) -> Business Development Department | M36: MGL00121 | N36: =VLOOKUP(M36,'Location Code Code'!$E$2:$F$22,2,FALSE) -> HEAD OFFICE NYASHISHI MWANZA | O36: MGL0012 | P36: =VLOOKUP(O36,'Business Code'!$C$1:$D$19,2,FALSE) -> TRADING OF COMERCIAL EXPLOSIVES | Q36: MGL001 | R36: =VLOOKUP(Q36,'Company Code'!$A$1:$B$7,2,FALSE) -> Mbogo Mining and General Supply Limited | U36: Being payment for security payment for the month of November 2024 | V36: 750000 | X36: =IF(V36="", W36, V36) -> 750000 | Y36: =IF(V36<>"","DR","CR") -> DR
A37: 02.01.2025 | B37: RV01-02012025 | D37: ANISET MABULA | E37: 57250100 | F37: =VLOOKUP(E37,'Improved Accounting codes'!C118:D2458,2,FALSE) -> Cash for office use Mbogo Mining and General Supply Limited | G37: 572501 | H37: =VLOOKUP(G37,'Improved Accounting codes'!A90:B2430,2,FALSE) -> Cash for Office Use | I37: BDD00102 | J37: =VLOOKUP(I37,'Section Code'!$B$1:$C$17,2,FALSE) -> Sales and Marketing Section | K37: BDD001 | L37: =VLOOKUP(K37,'Department Codes'!$A$1:$B$4,2,FALSE) -> Business Development Department | M37: MGL00121 | N37: =VLOOKUP(M37,'Location Code Code'!$E$2:$F$22,2,FALSE) -> HEAD OFFICE NYASHISHI MWANZA | O37: MGL0012 | P37: =VLOOKUP(O37,'Business Code'!$C$1:$D$19,2,FALSE) -> TRADING OF COMERCIAL EXPLOSIVES | Q37: MGL001 | R37: =VLOOKUP(Q37,'Company Code'!$A$1:$B$7,2,FALSE) -> Mbogo Mining and General Supply Limited | U37: Being payment for security payment for the month of November 2024 | W37: 750000 | X37: =IF(V37="", W37, V37) -> 750000 | Y37: =IF(V37<>"","DR","CR") -> CR
A38: 02.01.2025 | B38: RV01-02012025 | D38: ONESMO NIBENGO NMB 61810095948 | E38: 40240100 | F38: =VLOOKUP(E38,'Improved Accounting codes'!C119:D2459,2,FALSE) -> Fixed Asset Suppliers | G38: 402401 | H38: =VLOOKUP(G38,'Improved Accounting codes'!A91:B2431,2,FALSE) -> Fixed Asset Suppliers | I38: BDD00102 | J38: =VLOOKUP(I38,'Section Code'!$B$1:$C$17,2,FALSE) -> Sales and Marketing Section | K38: BDD001 | L38: =VLOOKUP(K38,'Department Codes'!$A$1:$B$4,2,FALSE) -> Business Development Department | M38: MGL00121 | N38: =VLOOKUP(M38,'Location Code Code'!$E$2:$F$22,2,FALSE) -> HEAD OFFICE NYASHISHI MWANZA | O38: MGL0012 | P38: =VLOOKUP(O38,'Business Code'!$C$1:$D$19,2,FALSE) -> TRADING OF COMERCIAL EXPLOSIVES | Q38: MGL001 | R38: =VLOOKUP(Q38,'Company Code'!$A$1:$B$7,2,FALSE) -> Mbogo Mining and General Supply Limited | U38: Being payment for purchase of iron steel 3m 11 pcs@21,000 | V38: 231000 | X38: =IF(V38="", W38, V38) -> 231000 | Y38: =IF(V38<>"","DR","CR") -> DR
A39: 02.01.2025 | B39: RV01-02012025 | D39: ONESMO NIBENGO NMB 61810095948 | E39: 57250100 | F39: =VLOOKUP(E39,'Improved Accounting codes'!C120:D2460,2,FALSE) -> Cash for office use Mbogo Mining and General Supply Limited | G39: 572501 | H39: =VLOOKUP(G39,'Improved Accounting codes'!A92:B2432,2,FALSE) -> Cash for Office Use | I39: BDD00102 | J39: =VLOOKUP(I39,'Section Code'!$B$1:$C$17,2,FALSE) -> Sales and Marketing Section | K39: BDD001 | L39: =VLOOKUP(K39,'Department Codes'!$A$1:$B$4,2,FALSE) -> Business Development Department | M39: MGL00121 | N39: =VLOOKUP(M39,'Location Code Code'!$E$2:$F$22,2,FALSE) -> HEAD OFFICE NYASHISHI MWANZA | O39: MGL0012 | P39: =VLOOKUP(O39,'Business Code'!$C$1:$D$19,2,FALSE) -> TRADING OF COMERCIAL EXPLOSIVES | Q39: MGL001 | R39: =VLOOKUP(Q39,'Company Code'!$A$1:$B$7,2,FALSE) -> Mbogo Mining and General Supply Limited | U39: Being payment for purchase of iron steel 3m 11 pcs@21,000 | W39: 231000 | X39: =IF(V39="", W39, V39) -> 231000 | Y39: =IF(V39<>"","DR","CR") -> CR
A40: 02.01.2025 | B40: RV01-02012025 | D40: ONESMO NIBENGO NMB 61810095948 | E40: 40240100 | F40: =VLOOKUP(E40,'Improved Accounting codes'!C121:D2461,2,FALSE) -> Fixed Asset Suppliers | G40: 402401 | H40: =VLOOKUP(G40,'Improved Accounting codes'!A93:B2433,2,FALSE) -> Fixed Asset Suppliers | I40: BDD00102 | J40: =VLOOKUP(I40,'Section Code'!$B$1:$C$17,2,FALSE) -> Sales and Marketing Section | K40: BDD001 | L40: =VLOOKUP(K40,'Department Codes'!$A$1:$B$4,2,FALSE) -> Business Development Department | M40: MGL00121 | N40: =VLOOKUP(M40,'Location Code Code'!$E$2:$F$22,2,FALSE) -> HEAD OFFICE NYASHISHI MWANZA | O40: MGL0012 | P40: =VLOOKUP(O40,'Business Code'!$C$1:$D$19,2,FALSE) -> TRADING OF COMERCIAL EXPLOSIVES | Q40: MGL001 | R40: =VLOOKUP(Q40,'Company Code'!$A$1:$B$7,2,FALSE) -> Mbogo Mining and General Supply Limited | U40: Being payment for purchase of iron steel 2m 12@15000 | V40: 180000 | X40: =IF(V40="", W40, V40) -> 180000 | Y40: =IF(V40<>"","DR","CR") -> DR
A41: 02.01.2025 | B41: RV01-02012025 | D41: ONESMO NIBENGO NMB 61810095948 | E41: 57250100 | F41: =VLOOKUP(E41,'Improved Accounting codes'!C122:D2462,2,FALSE) -> Cash for office use Mbogo Mining and General Supply Limited | G41: 572501 | H41: =VLOOKUP(G41,'Improved Accounting codes'!A94:B2434,2,FALSE) -> Cash for Office Use | I41: BDD00102 | J41: =VLOOKUP(I41,'Section Code'!$B$1:$C$17,2,FALSE) -> Sales and Marketing Section | K41: BDD001 | L41: =VLOOKUP(K41,'Department Codes'!$A$1:$B$4,2,FALSE) -> Business Development Department | M41: MGL00121 | N41: =VLOOKUP(M41,'Location Code Code'!$E$2:$F$22,2,FALSE) -> HEAD OFFICE NYASHISHI MWANZA | O41: MGL0012 | P41: =VLOOKUP(O41,'Business Code'!$C$1:$D$19,2,FALSE) -> TRADING OF COMERCIAL EXPLOSIVES | Q41: MGL001 | R41: =VLOOKUP(Q41,'Company Code'!$A$1:$B$7,2,FALSE) -> Mbogo Mining and General Supply Limited | U41: Being payment for purchase of iron steel 2m 12@15000 | W41: 180000 | X41: =IF(V41="", W41, V41) -> 180000 | Y41: =IF(V41<>"","DR","CR") -> CR
A42: 02.01.2025 | B42: RV01-02012025 | D42: ONESMO NIBENGO NMB 61810095948 | E42: 62760100 | F42: =VLOOKUP(E42,'Improved Accounting codes'!C123:D2463,2,FALSE) -> Tools | G42: 627601 | H42: =VLOOKUP(G42,'Improved Accounting codes'!A95:B2435,2,FALSE) -> Spare parts, Repair,Acetone and Maintenance | I42: BDD00102 | J42: =VLOOKUP(I42,'Section Code'!$B$1:$C$17,2,FALSE) -> Sales and Marketing Section | K42: BDD001 | L42: =VLOOKUP(K42,'Department Codes'!$A$1:$B$4,2,FALSE) -> Business Development Department | M42: MGL00121 | N42: =VLOOKUP(M42,'Location Code Code'!$E$2:$F$22,2,FALSE) -> HEAD OFFICE NYASHISHI MWANZA | O42: MGL0012 | P42: =VLOOKUP(O42,'Business Code'!$C$1:$D$19,2,FALSE) -> TRADING OF COMERCIAL EXPLOSIVES | Q42: MGL001 | R42: =VLOOKUP(Q42,'Company Code'!$A$1:$B$7,2,FALSE) -> Mbogo Mining and General Supply Limited | U42: Being payment for purchase of Nails 2 kg @6000 | V42: 12000 | X42: =IF(V42="", W42, V42) -> 12000 | Y42: =IF(V42<>"","DR","CR") -> DR
A43: 02.01.2025 | B43: RV01-02012025 | D43: ONESMO NIBENGO NMB 61810095948 | E43: 57250100 | F43: =VLOOKUP(E43,'Improved Accounting codes'!C124:D2464,2,FALSE) -> Cash for office use Mbogo Mining and General Supply Limited | G43: 572501 | H43: =VLOOKUP(G43,'Improved Accounting codes'!A96:B2436,2,FALSE) -> Cash for Office Use | I43: BDD00102 | J43: =VLOOKUP(I43,'Section Code'!$B$1:$C$17,2,FALSE) -> Sales and Marketing Section | K43: BDD001 | L43: =VLOOKUP(K43,'Department Codes'!$A$1:$B$4,2,FALSE) -> Business Development Department | M43: MGL00121 | N43: =VLOOKUP(M43,'Location Code Code'!$E$2:$F$22,2,FALSE) -> HEAD OFFICE NYASHISHI MWANZA | O43: MGL0012 | P43: =VLOOKUP(O43,'Business Code'!$C$1:$D$19,2,FALSE) -> TRADING OF COMERCIAL EXPLOSIVES | Q43: MGL001 | R43: =VLOOKUP(Q43,'Company Code'!$A$1:$B$7,2,FALSE) -> Mbogo Mining and General Supply Limited | U43: Being payment for purchase of Nails 2 kg @6000 | W43: 12000 | X43: =IF(V43="", W43, V43) -> 12000 | Y43: =IF(V43<>"","DR","CR") -> CR
...

Sheet JV TO UPLOAD
A1: Posting Date | B1: P.V.NO. | C1: CHQ N0. | D1: PAYEE | E1: Sub Account Code | F1: Section Code | G1: Location code | H1: Busines Code | I1: Currency | J1: EXCHANGE RATE | K1: Details | L1: Amount | M1: condtion | N1: AMOUNT
A2: 45659 | B2: N/A | C2: N/A | D2: CRDB BANK PLC | E2: 56150700 | F2: FAD00102 | G2: MGL00121 | H2: MGL0012 | I2: TZS | J2: 1 | K2: REF:19426ee2ed61dab3 AGENCY FT AB17358199306989206479:Flavian:K N/A | L2: 3000000 | M2: DR | N2: =J2*L2 -> 3000000
A3: 45659 | B3: N/A | C3: N/A | D3: CRDB BANK PLC | E3: 56150600 | F3: FAD00102 | G3: MGL00121 | H3: MGL0012 | I3: TZS | J3: 1 | K3: REF:19426ee2ed61dab3 AGENCY FT AB17358199306989206479:Flavian:K N/A | L3: 3000000 | M3: CR | N3: =J3*L3 -> 3000000
A4: 45659 | B4: RV01-02012025 | C4: N/A | D4: NEEMA RAPHAEL 0744979075 M -PESA | E4: 60160204 | F4: BDD00102 | G4: MGL00121 | H4: MGL0012 | I4: USD | J4: 2560.67 | K4: .Being payment for Casual labour 3 people@8000/= for six days | L4: 140 | M4: DR | N4: =J4*L4 -> 358493.8
A5: 45659 | B5: RV01-02012025 | C5: N/A | D5: NEEMA RAPHAEL 0744979075 M -PESA | E5: 57250100 | F5: BDD00102 | G5: MGL00121 | H5: MGL0012 | I5: USD | J5: 2560.67 | K5: .Being payment for Casual labour 3 people@8000/= for six days | L5: 140 | M5: CR | N5: =J5*L5 -> 358493.8

Sheet Sheet4
A1: 19/12/2024 | D1: BARNABAS ATHANAS NIBENGO | E1: ='Improved Accounting codes'!C1746 -> 67560103 | F1: =VLOOKUP(E1,'Improved Accounting codes'!C5:D2345,2,FALSE) -> Barnabas Athanas Nibengo | G1: ='Improved Accounting codes'!A1743 -> 675601 | H1: =VLOOKUP(G1,'Improved Accounting codes'!A5:B2345,2,FALSE) -> Uncategorised Expenses | I1: FAD00102 | J1: =VLOOKUP(I1,'Section Code'!B1:C17,2,FALSE) -> Finance Section | K1: FAD001 | L1: =VLOOKUP(K1,'Department Codes'!A1:B4,2,FALSE) -> Finance and Administration Department | M1: MGL00121 | N1: =VLOOKUP(M1,'Location Code Code'!E1:F22,2,FALSE) -> HEAD OFFICE NYASHISHI MWANZA | O1: MGL0011 | P1: =VLOOKUP(O1,'Business Code'!C1:D21,2,FALSE) -> MANUFACTUREING OF COMMERCIAL EXPLOSIVES | Q1: MGL001 | R1: =VLOOKUP(Q1,'Company Code'!A1:B7,2,FALSE) -> Mbogo Mining and General Supply Limited | U1: REF:193de55d43cf794d IB FT TO MPESA 0757851332 BARNABAS ATHANAS NIBENGO | V1: 650000
A2: 19/12/2024 | D2: BARNABAS ATHANAS NIBENGO | E2: 56150600 | F2: =VLOOKUP(E2,'Improved Accounting codes'!C6:D2346,2,FALSE) -> CRDB TZS:0150481116500 | G2: 561506 | H2: =VLOOKUP(G2,'Improved Accounting codes'!A6:B2346,2,FALSE) -> CRDB BANK PLC | I2: FAD00102 | J2: =VLOOKUP(I2,'Section Code'!B2:C18,2,FALSE) -> Finance Section | K2: FAD001 | L2: =VLOOKUP(K2,'Department Codes'!A2:B5,2,FALSE) -> Finance and Administration Department | M2: MGL00121 | N2: =VLOOKUP(M2,'Location Code Code'!E2:F23,2,FALSE) -> HEAD OFFICE NYASHISHI MWANZA | O2: MGL0011 | P2: =VLOOKUP(O2,'Business Code'!C2:D22,2,FALSE) -> MANUFACTUREING OF COMMERCIAL EXPLOSIVES | Q2: MGL001 | R2: =VLOOKUP(Q2,'Company Code'!A1:B7,2,FALSE) -> Mbogo Mining and General Supply Limited | U2: REF:193de55d43cf794d IB FT TO MPESA 0757851332 BARNABAS ATHANAS NIBENGO | W2: 650000
A3: 19.12.2024 | D3: CRDB BANK PLC | E3: 63860720 | F3: =VLOOKUP(E3,'Improved Accounting codes'!C7:D2347,2,FALSE) -> #N/A | G3: 638607 | H3: =VLOOKUP(G3,'Improved Accounting codes'!A7:B2347,2,FALSE) -> Bank Charges | I3: FAD00102 | J3: =VLOOKUP(I3,'Section Code'!B3:C19,2,FALSE) -> Finance Section | K3: FAD001 | L3: =VLOOKUP(K3,'Department Codes'!A2:B5,2,FALSE) -> Finance and Administration Department | M3: MGL00121 | N3: =VLOOKUP(M3,'Location Code Code'!E3:F24,2,FALSE) -> HEAD OFFICE NYASHISHI MWANZA | O3: MGL0011 | P3: =VLOOKUP(O3,'Business Code'!C2:D22,2,FALSE) -> MANUFACTUREING OF COMMERCIAL EXPLOSIVES | Q3: MGL001 | R3: =VLOOKUP(Q3,'Company Code'!A2:B8,2,FALSE) -> Mbogo Mining and General Supply Limited | U3: REF:193de55d43cf794d CHARGE: TRANSFER TO MPESA VIA IB | V3: 9067.8
A4: 19.12.2024 | D4: CRDB BANK PLC | E4: 56150600 | F4: =VLOOKUP(E4,'Improved Accounting codes'!C8:D2348,2,FALSE) -> CRDB TZS:0150481116500 | G4: 561506 | H4: =VLOOKUP(G4,'Improved Accounting codes'!A8:B2348,2,FALSE) -> CRDB BANK PLC | I4: FAD00102 | J4: =VLOOKUP(I4,'Section Code'!B3:C19,2,FALSE) -> Finance Section | K4: FAD001 | L4: =VLOOKUP(K4,'Department Codes'!A2:B5,2,FALSE) -> Finance and Administration Department | M4: MGL00121 | N4: =VLOOKUP(M4,'Location Code Code'!E3:F24,2,FALSE) -> HEAD OFFICE NYASHISHI MWANZA | O4: MGL0011 | P4: =VLOOKUP(O4,'Business Code'!C2:D22,2,FALSE) -> MANUFACTUREING OF COMMERCIAL EXPLOSIVES | Q4: MGL001 | R4: =VLOOKUP(Q4,'Company Code'!A2:B8,2,FALSE) -> Mbogo Mining and General Supply Limited | U4: REF:193de55d43cf794d CHARGE: TRANSFER TO MPESA VIA IB | W4: 9067.8
A5: 19.12.2024 | D5: CRDB BANK PLC | E5: 25520102 | F5: =VLOOKUP(E5,'Improved Accounting codes'!C9:D2349,2,FALSE) -> Loans to subsidiaries | G5: 255201 | H5: =VLOOKUP(G5,'Improved Accounting codes'!A9:B2349,2,FALSE) -> Recievables on loans | I5: FAD00102 | J5: =VLOOKUP(I5,'Section Code'!B3:C19,2,FALSE) -> Finance Section | K5: FAD001 | L5: =VLOOKUP(K5,'Department Codes'!A2:B5,2,FALSE) -> Finance and Administration Department | M5: MGL00121 | N5: =VLOOKUP(M5,'Location Code Code'!E3:F24,2,FALSE) -> HEAD OFFICE NYASHISHI MWANZA | O5: MGL0011 | P5: =VLOOKUP(O5,'Business Code'!C2:D22,2,FALSE) -> MANUFACTUREING OF COMMERCIAL EXPLOSIVES | Q5: MGL001 | R5: =VLOOKUP(Q5,'Company Code'!A2:B8,2,FALSE) -> Mbogo Mining and General Supply Limited | U5: VAT (18%) PAYABLE ON COMMISSION AND FEES : FULL | V5: 1632.2
A6: 19.12.2024 | D6: CRDB BANK PLC | E6: 56150600 | F6: =VLOOKUP(E6,'Improved Accounting codes'!C10:D2350,2,FALSE) -> CRDB TZS:0150481116500 | G6: 561506 | H6: =VLOOKUP(G6,'Improved Accounting codes'!A10:B2350,2,FALSE) -> CRDB BANK PLC | I6: FAD00102 | J6: =VLOOKUP(I6,'Section Code'!B3:C19,2,FALSE) -> Finance Section | K6: FAD001 | L6: =VLOOKUP(K6,'Department Codes'!A2:B5,2,FALSE) -> Finance and Administration Department | M6: MGL00121 | N6: =VLOOKUP(M6,'Location Code Code'!E3:F24,2,FALSE) -> HEAD OFFICE NYASHISHI MWANZA | O6: MGL0011 | P6: =VLOOKUP(O6,'Business Code'!C2:D22,2,FALSE) -> MANUFACTUREING OF COMMERCIAL EXPLOSIVES | Q6: MGL001 | R6: =VLOOKUP(Q6,'Company Code'!A2:B8,2,FALSE) -> Mbogo Mining and General Supply Limited | U6: VAT (18%) PAYABLE ON COMMISSION AND FEES : FULL | W6: 1632.2
A7: 19.12.2024 | D7: EPIFANIA FRANK ODANCE | E7: 57250100 | F7: =VLOOKUP(E7,'Improved Accounting codes'!C11:D2351,2,FALSE) -> Cash for office use Mbogo Mining and General Supply Limited | G7: 572501 | H7: =VLOOKUP(G7,'Improved Accounting codes'!A11:B2351,2,FALSE) -> Cash for Office Use | I7: FAD00102 | J7: =VLOOKUP(I7,'Section Code'!B3:C19,2,FALSE) -> Finance Section | K7: FAD001 | L7: =VLOOKUP(K7,'Department Codes'!A2:B5,2,FALSE) -> Finance and Administration Department | M7: MGL00121 | N7: =VLOOKUP(M7,'Location Code Code'!E3:F24,2,FALSE) -> HEAD OFFICE NYASHISHI MWANZA | O7: MGL0011 | P7: =VLOOKUP(O7,'Business Code'!C2:D22,2,FALSE) -> MANUFACTUREING OF COMMERCIAL EXPLOSIVES | Q7: MGL001 | R7: =VLOOKUP(Q7,'Company Code'!A2:B8,2,FALSE) -> Mbogo Mining and General Supply Limited | U7: REF:193decad7dcb2826 IB FT TO MPESA 0765427622 EPIFANIA FRANK ODANCE | V7: 200000
A8: 19.12.2024 | D8: EPIFANIA FRANK ODANCE | E8: 56150600 | F8: =VLOOKUP(E8,'Improved Accounting codes'!C12:D2352,2,FALSE) -> CRDB TZS:0150481116500 | G8: 561506 | H8: =VLOOKUP(G8,'Improved Accounting codes'!A12:B2352,2,FALSE) -> CRDB BANK PLC | I8: FAD00102 | J8: =VLOOKUP(I8,'Section Code'!B3:C19,2,FALSE) -> Finance Section | K8: FAD001 | L8: =VLOOKUP(K8,'Department Codes'!A2:B5,2,FALSE) -> Finance and Administration Department | M8: MGL00121 | N8: =VLOOKUP(M8,'Location Code Code'!E3:F24,2,FALSE) -> HEAD OFFICE NYASHISHI MWANZA | O8: MGL0011 | P8: =VLOOKUP(O8,'Business Code'!C2:D22,2,FALSE) -> MANUFACTUREING OF COMMERCIAL EXPLOSIVES | Q8: MGL001 | R8: =VLOOKUP(Q8,'Company Code'!A2:B8,2,FALSE) -> Mbogo Mining and General Supply Limited | U8: REF:193decad7dcb2826 IB FT TO MPESA 0765427622 EPIFANIA FRANK ODANCE | W8: 200000
A9: 19.12.2024 | D9: CRDB BANK PLC | E9: 63860720 | F9: =VLOOKUP(E9,'Improved Accounting codes'!C13:D2353,2,FALSE) -> #N/A | G9: 638607 | H9: =VLOOKUP(G9,'Improved Accounting codes'!A13:B2353,2,FALSE) -> Bank Charges | I9: FAD00102 | J9: =VLOOKUP(I9,'Section Code'!B3:C19,2,FALSE) -> Finance Section | K9: FAD001 | L9: =VLOOKUP(K9,'Department Codes'!A2:B5,2,FALSE) -> Finance and Administration Department | M9: MGL00121 | N9: =VLOOKUP(M9,'Location Code Code'!E3:F24,2,FALSE) -> HEAD OFFICE NYASHISHI MWANZA | O9: MGL0011 | P9: =VLOOKUP(O9,'Business Code'!C2:D22,2,FALSE) -> MANUFACTUREING OF COMMERCIAL EXPLOSIVES | Q9: MGL001 | R9: =VLOOKUP(Q9,'Company Code'!A2:B8,2,FALSE) -> Mbogo Mining and General Supply Limited | U9: REF:193decad7dcb2826 CHARGE: TRANSFER TO MPESA VIA IB | V9: 6525.42
A10: 19.12.2024 | D10: CRDB BANK PLC | E10: 56150600 | F10: =VLOOKUP(E10,'Improved Accounting codes'!C14:D2354,2,FALSE) -> CRDB TZS:0150481116500 | G10: 561506 | H10: =VLOOKUP(G10,'Improved Accounting codes'!A14:B2354,2,FALSE) -> CRDB BANK PLC | I10: FAD00102 | J10: =VLOOKUP(I10,'Section Code'!B3:C19,2,FALSE) -> Finance Section | K10: FAD001 | L10: =VLOOKUP(K10,'Department Codes'!A2:B5,2,FALSE) -> Finance and Administration Department | M10: MGL00121 | N10: =VLOOKUP(M10,'Location Code Code'!E3:F24,2,FALSE) -> HEAD OFFICE NYASHISHI MWANZA | O10: MGL0011 | P10: =VLOOKUP(O10,'Business Code'!C2:D22,2,FALSE) -> MANUFACTUREING OF COMMERCIAL EXPLOSIVES | Q10: MGL001 | R10: =VLOOKUP(Q10,'Company Code'!A2:B8,2,FALSE) -> Mbogo Mining and General Supply Limited | U10: REF:193decad7dcb2826 CHARGE: TRANSFER TO MPESA VIA IB | W10: 6525.42
A11: 19.12.2024 | D11: CRDB BANK PLC | E11: 25520102 | F11: =VLOOKUP(E11,'Improved Accounting codes'!C15:D2355,2,FALSE) -> Loans to subsidiaries | G11: 255201 | H11: =VLOOKUP(G11,'Improved Accounting codes'!A15:B2355,2,FALSE) -> Recievables on loans | I11: FAD00102 | J11: =VLOOKUP(I11,'Section Code'!B3:C19,2,FALSE) -> Finance Section | K11: FAD001 | L11: =VLOOKUP(K11,'Department Codes'!A2:B5,2,FALSE) -> Finance and Administration Department | M11: MGL00121 | N11: =VLOOKUP(M11,'Location Code Code'!E3:F24,2,FALSE) -> HEAD OFFICE NYASHISHI MWANZA | O11: MGL0011 | P11: =VLOOKUP(O11,'Business Code'!C2:D22,2,FALSE) -> MANUFACTUREING OF COMMERCIAL EXPLOSIVES | Q11: MGL001 | R11: =VLOOKUP(Q11,'Company Code'!A2:B8,2,FALSE) -> Mbogo Mining and General Supply Limited | U11: VAT (18%) PAYABLE ON COMMISSION AND FEES : FULL | V11: 1174.58
D12: CRDB BANK PLC | E12: 56150600 | F12: =VLOOKUP(E12,'Improved Accounting codes'!C16:D2356,2,FALSE) -> CRDB TZS:0150481116500 | G12: 561506 | H12: =VLOOKUP(G12,'Improved Accounting codes'!A16:B2356,2,FALSE) -> CRDB BANK PLC | I12: FAD00102 | J12: =VLOOKUP(I12,'Section Code'!B3:C19,2,FALSE) -> Finance Section | K12: FAD001 | L12: =VLOOKUP(K12,'Department Codes'!A2:B5,2,FALSE) -> Finance and Administration Department | M12: MGL00121 | N12: =VLOOKUP(M12,'Location Code Code'!E3:F24,2,FALSE) -> HEAD OFFICE NYASHISHI MWANZA | O12: MGL0011 | P12: =VLOOKUP(O12,'Business Code'!C2:D22,2,FALSE) -> MANUFACTUREING OF COMMERCIAL EXPLOSIVES | Q12: MGL001 | R12: =VLOOKUP(Q12,'Company Code'!A2:B8,2,FALSE) -> Mbogo Mining and General Supply Limited | U12: VAT (18%) PAYABLE ON COMMISSION AND FEES : FULL | W12: 1174.58
A13: 19.12.2024 | D13: JONATHAN KASHIMIR MUSHI | E13: 56150600 | F13: =VLOOKUP(E13,'Improved Accounting codes'!C17:D2357,2,FALSE) -> CRDB TZS:0150481116500 | G13: 561506 | H13: =VLOOKUP(G13,'Improved Accounting codes'!A17:B2357,2,FALSE) -> CRDB BANK PLC | I13: BDD00101 | J13: =VLOOKUP(I13,'Section Code'!B3:C19,2,FALSE) -> General Supply Section | K13: BDD001 | L13: =VLOOKUP(K13,'Department Codes'!A2:B5,2,FALSE) -> Business Development Department | M13: MGL0014 | N13: =VLOOKUP(M13,'Location Code Code'!C1:D22,2,FALSE) -> GENERAL SUPPLY | O13: MGL00141 | P13: =VLOOKUP(O13,'Location Code Code'!E1:F22,2,FALSE) -> HEAD OFFICE NYASHISHI MWANZA | Q13: MGL001 | R13: =VLOOKUP(Q13,'Company Code'!A2:B8,2,FALSE) -> Mbogo Mining and General Supply Limited | U13: JONATHAN KASHIMIR MUSHI CASH DEPOSITS | V13: 15660920
A14: 21.12.2024 | D14: JONATHAN KASHIMIR MUSHI | E14: 67560105 | F14: =VLOOKUP(E14,'Improved Accounting codes'!C7:D2347,2,FALSE) -> Jonathan Kashimir Mushi | G14: 675601 | H14: =VLOOKUP(G14,'Improved Accounting codes'!A7:B2347,2,FALSE) -> Uncategorised Expenses | I14: BDD00101 | J14: =VLOOKUP(I14,'Section Code'!B3:C19,2,FALSE) -> General Supply Section | K14: BDD001 | L14: =VLOOKUP(K14,'Department Codes'!A2:B5,2,FALSE) -> Business Development Department | M14: MGL0014 | N14: =VLOOKUP(M14,'Location Code Code'!C2:D23,2,FALSE) -> GENERAL SUPPLY | O14: MGL00141 | P14: =VLOOKUP(O14,'Location Code Code'!E2:F23,2,FALSE) -> HEAD OFFICE NYASHISHI MWANZA | Q14: MGL001 | R14: =VLOOKUP(Q14,'Company Code'!A2:B8,2,FALSE) -> Mbogo Mining and General Supply Limited | U14: JONATHAN KASHIMIR MUSHI CASH DEPOSITS | W14: 15660920
A15: 21.12.2024 | D15: CRDB BANK PLC | E15: 63860720 | F15: =VLOOKUP(E15,'Improved Accounting codes'!C9:D2349,2,FALSE) -> #N/A | G15: 638607 | H15: =VLOOKUP(G15,'Improved Accounting codes'!A9:B2349,2,FALSE) -> Bank Charges | I15: FAD00102 | J15: =VLOOKUP(I15,'Section Code'!B3:C19,2,FALSE) -> Finance Section | K15: FAD001 | L15: =VLOOKUP(K15,'Department Codes'!A2:B5,2,FALSE) -> Finance and Administration Department | M15: MGL00121 | N15: =VLOOKUP(M15,'Location Code Code'!E3:F24,2,FALSE) -> HEAD OFFICE NYASHISHI MWANZA | O15: MGL0011 | P15: =VLOOKUP(O15,'Business Code'!C2:D22,2,FALSE) -> MANUFACTUREING OF COMMERCIAL EXPLOSIVES | Q15: MGL001 | R15: =VLOOKUP(Q15,'Company Code'!A2:B8,2,FALSE) -> Mbogo Mining and General Supply Limited | U15: Monthly Maintenance Fee | V15: 13000
